<?xml version="1.0" encoding="utf-8"?>
<!-- This URDF was automatically created by SolidWorks to URDF Exporter! Originally created by Stephen Brawner (brawner@gmail.com) 
     Commit Version: 1.6.0-4-g7f85cfe  Build Version: 1.6.7995.38578
     For more information, please see http://wiki.ros.org/sw_urdf_exporter -->
<robot
  name="rover_description">
  <link
    name="base_link">
    <inertial>
      <origin
        xyz="-0.0028373459861756 -5.48612014375435E-06 -0.406897744418785"
        rpy="0 0 0" />
      <mass
        value="36.4090186352555" />
      <inertia
        ixx="1.14989797110002"
        ixy="-2.43735391975653E-05"
        ixz="0.0182296282265289"
        iyy="0.875741628239762"
        iyz="-3.36012534940307E-05"
        izz="1.2152774654334" />
    </inertial>
    <visual>
      <origin
        xyz="0 0 0"
        rpy="0 0 0" />
      <geometry>
        <mesh
          filename="package://rover_description/meshes/base_link.STL" />
      </geometry>
      <material
        name="">
        <color
          rgba="0.792156862745098 0.819607843137255 0.933333333333333 1" />
      </material>
    </visual>
    <collision>
      <origin
        xyz="0 0 0"
        rpy="0 0 0" />
      <geometry>
        <mesh
          filename="package://rover_description/meshes/base_link.STL" />
      </geometry>
    </collision>
  </link>
  <link
    name="link_BR">
    <inertial>
      <origin
        xyz="-0.650344956000871 0.844999999999999 9.43689570931383E-16"
        rpy="0 0 0" />
      <mass
        value="8.03286499782857" />
      <inertia
        ixx="0.0518365067203933"
        ixy="3.78750231068312E-18"
        ixz="-4.29627568261947E-18"
        iyy="0.0735497696989295"
        iyz="-2.51986915923884E-19"
        izz="0.0518365067203933" />
    </inertial>
    <visual>
      <origin
        xyz="0 0 0"
        rpy="0 0 0" />
      <geometry>
        <mesh
          filename="package://rover_description/meshes/link_BR.STL" />
      </geometry>
      <material
        name="">
        <color
          rgba="0.792156862745098 0.819607843137255 0.933333333333333 1" />
      </material>
    </visual>
    <collision>
      <origin
        xyz="0 0 0"
        rpy="0 0 0" />
      <geometry>
        <mesh
          filename="package://rover_description/meshes/link_BR.STL" />
      </geometry>
    </collision>
  </link>
  <joint
    name="joint_BR"
    type="continuous">
    <origin
      xyz="0.29633 -0.46 -0.135"
      rpy="0 0 0" />
    <parent
      link="base_link" />
    <child
      link="link_BR" />
    <axis
      xyz="0 -1 0" />
  </joint>
  <link
    name="link_BL">
    <inertial>
      <origin
        xyz="-0.65034495600087 -0.845 -8.32667268468867E-17"
        rpy="0 0 0" />
      <mass
        value="8.03286499782857" />
      <inertia
        ixx="0.0518365067203933"
        ixy="3.11534428966492E-18"
        ixz="-8.13019280466119E-18"
        iyy="0.0735497696989295"
        iyz="-1.2345414931867E-18"
        izz="0.0518365067203933" />
    </inertial>
    <visual>
      <origin
        xyz="0 0 0"
        rpy="0 0 0" />
      <geometry>
        <mesh
          filename="package://rover_description/meshes/link_BL.STL" />
      </geometry>
      <material
        name="">
        <color
          rgba="0.792156862745098 0.819607843137255 0.933333333333333 1" />
      </material>
    </visual>
    <collision>
      <origin
        xyz="0 0 0"
        rpy="0 0 0" />
      <geometry>
        <mesh
          filename="package://rover_description/meshes/link_BL.STL" />
      </geometry>
    </collision>
  </link>
  <joint
    name="joint_BL"
    type="continuous">
    <origin
      xyz="0.29633 0.46 -0.135"
      rpy="0 0 0" />
    <parent
      link="base_link" />
    <child
      link="link_BL" />
    <axis
      xyz="0 -1 0" />
  </joint>
  <link
    name="link_FR">
    <inertial>
      <origin
        xyz="0.65034495600087 0.845 1.66533453693773E-16"
        rpy="0 0 0" />
      <mass
        value="8.03286499782856" />
      <inertia
        ixx="0.0518365067203933"
        ixy="-1.81890518556632E-18"
        ixz="1.27498109049398E-17"
        iyy="0.0735497696989295"
        iyz="-1.87977761238893E-18"
        izz="0.0518365067203933" />
    </inertial>
    <visual>
      <origin
        xyz="0 0 0"
        rpy="0 0 0" />
      <geometry>
        <mesh
          filename="package://rover_description/meshes/link_FR.STL" />
      </geometry>
      <material
        name="">
        <color
          rgba="0.792156862745098 0.819607843137255 0.933333333333333 1" />
      </material>
    </visual>
    <collision>
      <origin
        xyz="0 0 0"
        rpy="0 0 0" />
      <geometry>
        <mesh
          filename="package://rover_description/meshes/link_FR.STL" />
      </geometry>
    </collision>
  </link>
  <joint
    name="joint_FR"
    type="continuous">
    <origin
      xyz="-0.35401 -0.46 -0.135"
      rpy="0 0 0" />
    <parent
      link="base_link" />
    <child
      link="link_FR" />
    <axis
      xyz="0 -1 0" />
  </joint>
  <link
    name="link_FL">
    <inertial>
      <origin
        xyz="0.65034495600087 -0.845 1.11022302462516E-16"
        rpy="0 0 0" />
      <mass
        value="8.03286499782856" />
      <inertia
        ixx="0.0518365067203933"
        ixy="-1.9451979284797E-18"
        ixz="1.76553429943318E-17"
        iyy="0.0735497696989294"
        iyz="-3.99958369781651E-19"
        izz="0.0518365067203933" />
    </inertial>
    <visual>
      <origin
        xyz="0 0 0"
        rpy="0 0 0" />
      <geometry>
        <mesh
          filename="package://rover_description/meshes/link_FL.STL" />
      </geometry>
      <material
        name="">
        <color
          rgba="0.792156862745098 0.819607843137255 0.933333333333333 1" />
      </material>
    </visual>
    <collision>
      <origin
        xyz="0 0 0"
        rpy="0 0 0" />
      <geometry>
        <mesh
          filename="package://rover_description/meshes/link_FL.STL" />
      </geometry>
    </collision>
  </link>
  <joint
    name="joint_FL"
    type="continuous">
    <origin
      xyz="-0.35401 0.46 -0.135"
      rpy="0 0 0" />
    <parent
      link="base_link" />
    <child
      link="link_FL" />
    <axis
      xyz="0 -1 0" />
  </joint>
</robot>